Workbook

Sheet Automate
A1: Unax Agote: Cambia por 800.000 € a Costa norte | B1: =MID(A1,FIND(" a ",A1)+2,LEN(A1)-FIND("a",A1)-1) | C1: =MID(A1,FIND("por ",A1)+4,FIND("€",A1)-FIND("por ",A1)-4-1) | D1: =MID(A1,1,FIND(": ",A1)-1)
A2: Yayo: Cambia por 743.400 € a Llaule | B2: =MID(A2,FIND(" a ",A2)+2,LEN(A2)-FIND("a",A2)-1) | C2: =MID(A2,FIND("por ",A2)+4,FIND("€",A2)-FIND("por ",A2)-4-1) | D2: =MID(A2,1,FIND(": ",A2)-1)
A3: Marvel: Cambia por 2.260.000 € a Llaule | B3: =MID(A3,FIND(" a ",A3)+2,LEN(A3)-FIND("a",A3)-1) | C3: =MID(A3,FIND("por ",A3)+4,FIND("€",A3)-FIND("por ",A3)-4-1) | D3: =MID(A3,1,FIND(": ",A3)-1)

Sheet Guacamayos
A1: Jugadores Iniciales | B1: Valor dia 0 | C1: Altas | D1: Gastado | E1: Bajas | F1: Ingresado | G1: Gastado Total | H1: Valor Plantilla Actual | I1: Beneficio J | K1: Ultima Actualización | L1: =TODAY()
A2: Plamen Andreev | B2: 3380000 | C2: Mario Climent | D2: 4000000 | E2: Manu Justo | F2: 1068400 | G2: =SUM(D:D) | H2: 38300000 | I2: 1130000 | J2: J2 | K2: 45936
A3: Nico Ratti | B3: 470000 | C3: Álex Calatrava | D3: 8000000 | E3: Nico Ratti | F3: 423200 | I3: 800000 | J3: J3
A4: Francisco Montero | B4: 2330000 | C4: Amatucci | D4: 3300000 | E4: Isaac Obeng | F4: 191500 | G4: Ingresado Total | H4: Beneficio Total Jornadas | I4: 710000 | J4: J4 | K4: Compras | L4: =COUNT(Guacamayos!$D$2:$D$14)
A5: Diego Sánchez | B5: 1870000 | C5: Aitor Córdoba | D5: 4500000 | E5: Saúl del Cerro | F5: 252900 | G5: =SUM(F:F) | H5: =SUM(Guacamayos!$I$2:$I$7) | I5: 790000 | J5: J5 | K5: Ventas | L5: =COUNT(Guacamayos!$F$2:$F$18)
A6: Juan Gutiérrez | B6: 2850000 | C6: Palomares | D6: 900000 | E6: Plamen Andreev | F6: 3036900 | I6: 720000 | J6: J6
A7: Juanma Herzog | B7: 2210000 | C7: David Larrubia | D7: 8500000 | E7: Alcaraz | F7: 1808100 | G7: Saldo Inicial | H7: Beneficio | I7: 1230000 | J7: J7
A8: Jorge Moreno | B8: 150000 | C8: Adrián Rodríguez | D8: 1680000 | E8: Juanma Herzog | F8: 2101900 | G8: 18960000 | H8: =G14-G8+H2-(40000000-G8)-H5 | J8: J8
A9: Iván Gil | B9: 1480000 | C9: Selvi Clua | D9: 720000 | E9: Xavi Moreno | F9: 320000 | J9: J9
A10: Peio Canales | B10: 1620000 | C10: García Pascual | D10: 3700000 | E10: Jorge Moreno | F10: 145700 | G10: Ofrecer | J10: J10
A11: Alcaraz | B11: 1860000 | C11: Naim García | D11: 1290000 | E11: Palomares | F11: 666200 | G11: =G14+H2/4 | J11: J11
A12: Marc-Olivier Doué | B12: 940000 | C12: Javi Moreno | D12: 300000 | E12: Marc-Olivier Doué | F12: 862000 | J12: J12
A13: Saúl del Cerro | B13: 260000 | C13: Raúl Lizoain | D13: 2260000 | E13: Diego Sánchez | F13: 2831800 | G13: Presupuesto | J13: J13
A14: Manu Justo | B14: 1100000 | C14: Juanmi Latasa | D14: 5370000 | E14: Selvi Clua | F14: 520200 | G14: =G8+G5-G2+H5 | J14: J14
A15: Xavi Moreno | B15: 320000 | E15: Adrián Rodríguez | F15: 1680300 | J15: J15
A16: Isaac Obeng | B16: 200000 | E16: Iván Gil | F16: 3132600 | J16: J16
B17: =SUM(B2:B16) | E17: Juan Gutiérrez | F17: 1983100 | J17: J17
E18: Francisco Montero | F18: 2834100 | J18: J18
J19: J19
J20: J20
J21: J21
J22: J22
J23: J23
J24: J24
J25: J25
J26: J26
J27: J27
J28: J28
J29: J29
J30: J30
... J42: J42

Sheet Cachoneros Mantilla Bésalo
C1: Altas | D1: Gastado | E1: Bajas | F1: Ingresado | G1: Gastado Total | H1: Valor Plantilla Actual | I1: Beneficio J | K1: Ultima Actualización | L1: =TODAY()
A2: Dani Jiménez | B2: 2610000 | C2: Lander Olaetxea | D2: 3180000 | E2: Gui Guedes | F2: 277600 | G2: =SUM(D:D) | H2: 38990000 | I2: 760000 | J2: J2 | K2: 45936
A3: Dani Martín | B3: 250000 | C3: Marc Cardona | D3: 770100 | E3: Mateo Mejía | F3: 1190000 | I3: 990000 | J3: J3
A4: Gregorio Sierra | B4: 2200000 | C4: Adrián Rodríguez | D4: 670110 | E4: Adrián Rodríguez | F4: 1680000 | G4: Ingresado Total | H4: Beneficio Total Jornadas | I4: 930000 | J4: J4 | K4: Compras | L4: =COUNT('Cachoneros Mantilla Bésalo'!$D$2:$D$14)
A5: Gael Alonso | B5: 850000 | C5: Jastin Garcia | D5: 691000 | E5: Aritz Aldasoro | F5: 3607900 | G5: =SUM(F:F) | H5: =SUM('Cachoneros Mantilla Bésalo'!$I$2:$I$7) | I5: 910000 | J5: J5 | K5: Ventas | L5: =COUNT('Cachoneros Mantilla Bésalo'!$F$2:$F$17)
A6: Marc Bombardó | B6: 770000 | C6: Iván Morante | D6: 5000001 | E6: Lander Olaetxea | F6: 2287000 | I6: 1110000 | J6: J6
A7: Nikola Milicic | B7: 240000 | C7: Milos Lukovic | D7: 7681000 | E7: Marc Cardona | F7: 645000 | G7: Saldo Inicial | H7: Beneficio | I7: 540000 | J7: J7
A8: Marcos Luna | B8: 1320000 | C8: Etienne Eto'o | D8: 1540000 | E8: Mario González | F8: 1339400 | G8: 18940000 | H8: =G14-G8+H2-(40000000-G8)-H5 | J8: J8
A9: David González | B9: 790000 | C9: Iñigo Vicente | D9: 17632789 | E9: Pablo Sáenz | F9: 2000000 | J9: J9
A10: Aritz Aldasoro | B10: 4310000 | C10: Piña | D10: 1192000 | E10: Gregorio Sierra | F10: 3500000 | G10: Ofrecer | J10: J10
A11: Izan Merino | B11: 2190000 | C11: Gorka Carrera | D11: 1720000 | E11: Dani Martín | F11: 197200 | G11: =G14+H2/4 | J11: J11
A12: Juan Pedro | B12: 350000 | C12: Aritz Aldasoro | D12: 3130000 | E12: Nikola Milicic | F12: 198900 | J12: J12
A13: Gui Guedes | B13: 330000 | C13: Gaspar Campos | D13: 3011000 | E13: Milos Lukovic | F13: 4107800 | G13: Presupuesto | J13: J13
A14: Mateo Mejía | B14: 520000 | C14: Luis Chacón | D14: 1890000 | E14: Etienne Eto'o | F14: 921800 | G14: =G8+G5-G2+H5 | J14: J14
A15: Pablo Sáenz | B15: 2450000 | E15: Marcos Luna | F15: 966100 | J15: J15
A16: Mario González | B16: 1880000 | E16: Izan Merino | F16: 1381800 | J16: J16
B17: =SUM(B2:B16) | E17: Gorka Carrera | F17: 1460000 | J17: J17
J18: J18
J19: J19
J20: J20
J21: J21
J22: J22
J23: J23
J24: J24
J25: J25
J26: J26
J27: J27
J28: J28
J29: J29
... J42: J42

Sheet Llaule
A1: Altas | B1: Pérdidas | C1: Bajas | D1: Ingresos | E1: Total Ingresos | F1: Valor Inicial | G1: Beneficio J | I1: Ultima Actualización | J1: =TODAY()
A2: Brian Cipenga | B2: 1160000 | C2: Marcos de Sousa | D2: 3000000 | E2: =SUM(D:D) | F2: 21250000 | G2: 930000 | H2: J2 | I2: 45936
A3: Ekain Díaz | B3: 190000 | C3: Eric Curbelo | D3: 1050000 | G3: 750000 | H3: J3
A4: Moussa Diakité | B4: 2860000 | C4: Jair | D4: 1040000 | E4: Total Perdidas | F4: Valor Actual | G4: 790000 | H4: J4 | I4: Compras | J4: =COUNT(Llaule!$B$2:$B$32)+2
A5: Áron Yaakobishvili | B5: 2000000 | C5: Ortuño | D5: 3690700 | E5: =SUM(B:B) | F5: 44840000 | G5: 750000 | H5: J5 | I5: Ventas | J5: =COUNT(Llaule!$D$2:$D$27)+2
A6: Bicho | B6: 1200000 | C6: Ronaldo | D6: 519400 | G6: 1030000 | H6: J6
A7: Mika Mármol | B7: 4160000 | C7: Brais Martinez | D7: 323000 | E7: Saldo Inicial | F7: Total de beneficio Jornadas | G7: 1150000 | H7: J7
A8: Mario Jimenez | B8: 250000 | C8: Arnau Rafus | D8: 190000 | E8: 18750000 | F8: =SUM(Llaule!$G$2:$G$43) | H8: J8
A9: David Torres | B9: 1560000 | C9: Ayman Arguigue | D9: 165300 | H9: J9
A10: Riki Rodríguez | B10: 3840000 | C10: Nico Ratti | D10: 551100 | E10: Saldo Actual | F10: Beneficio | H10: J10
A11: Juan Pérez | B11: 400000 | C11: Saul Garcia | D11: 908300 | E11: =E8+E2-E5+F8 | F11: =E11-E8+F5-F2-F8 | H11: J11
A12: Íñigo Sainz-Maza | B12: 2160000 | C12: David Torres | D12: 6500000 | H12: J12
A13: Juan Larios | B13: 1560000 | C13: Mario Jimenez | D13: 240600 | F13: Ofrecer | H13: J13
A14: Yayo | B14: 743400 | C14: Íñigo Sainz-Maza | D14: 2000000 | F14: =E11+F5/4 | H14: J14
A15: Marvel | B15: 2260000 | C15: Cristian Rodríguez | D15: 1012100 | H15: J15
A16: Arnau Puigmal | B16: 2760000 | C16: Carlos Dotor | D16: 2465900 | H16: J16
A17: Raúl Lizoain | B17: 1260000 | C17: Ekain Díaz | D17: 145200 | H17: J17
A18: Adu Ares | B18: 980000 | C18: Arnau Puigmal | D18: 2342500 | H18: J18
A19: Paulino | B19: 4220000 | C19: Paulino | D19: 3940000 | H19: J19
A20: Juanmi Latasa | B20: 5760000 | C20: Juan Larios | D20: 963700 | H20: J20
A21: Selu Diallo | B21: 650000 | C21: André Horta | D21: 2255400 | H21: J21
A22: Pau Sans | B22: 1500000 | C22: Juan Pérez | D22: 268800 | H22: J22
A23: Ontiveros | B23: 7260000 | C23: Raúl Lizoain | D23: 2260000 | H23: J23
A24: Nico Ratti | B24: 416000 | C24: Pau Sans | D24: 1120400 | H24: J24
A25: Arana | B25: 4160000 | C25: Mohamed Bouldini | D25: 649900 | H25: J25
A26: Diego González | B26: 360000 | C26: Juanmi Latasa | D26: 5370000 | H26: J26
A27: Pedro Alemañ | B27: 1860000 | C27: Brian Cipenga | D27: 5800000 | H27: J27
A28: Nélson Monte | B28: 3460000 | H28: J28
A29: Jefté Betancor | B29: 820000 | H29: J29
A30: Duk | B30: 6880000 | H30: J30
A31: Ramón Enríquez | B31: 380000 | H31: J31
A32: Sergio Cubero | B32: 4180000 | H32: J32
H33: J33
H34: J34
H35: J35
H36: J36
H37: J37
H38: J38
H39: J39
H40: J40
...

Sheet Steaua de grifo
C1: Altas | D1: Gastado | E1: Bajas | F1: Ingresado | G1: Gastado Total | H1: Valor Plantilla Actual | I1: Beneficio | K1: Ultima Actualización | L1: =TODAY()
A2: Gaëtan Poussin | B2: 2020000 | C2: Paulino | D2: 4050000 | E2: Gaëtan Poussin | F2: 1986800 | G2: =SUM(D:D) | H2: 42270000 | I2: 990000 | J2: J2 | K2: 45936
A3: Jesús Owono | B3: 2290000 | C3: Peru Rodríguez | D3: 1530030 | E3: Michal Willmann | F3: 736700 | I3: 1200000 | J3: J3
A4: Adrián Pica | B4: 2000000 | C4: Ximo Navarro | D4: 3270000 | E4: Dani Requena | F4: 993000 | G4: Ingresado Total | H4: Beneficio Total Jornadas | I4: 690000 | J4: J4 | K4: Compras | L4: =COUNT('Steaua de grifo'!$D$2:$D$17)
A5: Arnau Comas | B5: 1480000 | C5: Guti | D5: 3570000 | E5: Jaouab | F5: 793200 | G5: =SUM(F:F) | H5: =SUM('Steaua de grifo'!$I$2:$I$7) | I5: 710000 | J5: J5 | K5: Ventas | L5: =COUNT('Steaua de grifo'!$F$2:$F$18)
A6: Alex Suárez | B6: 2910000 | C6: Álvaro Rodríguez | D6: 800000 | E6: Anuar | F6: 2976100 | I6: 950000 | J6: J6
A7: Pastoriza | B7: 390000 | C7: Higinio | D7: 1720000 | E7: Alex Suárez | F7: 2120400 | G7: Saldo Inicial | H7: Beneficio | I7: 1090000 | J7: J7
A8: Youness Lachhab | B8: 490000 | C8: Min-su | D8: 1230000 | E8: Gabriel Barès | F8: 175300 | G8: 18790000 | H8: =G14-G8+H2-(40000000-G8)-H5 | J8: J8
A9: Aarón Ochoa | B9: 640000 | C9: Miguel Atienza | D9: 3520000 | E9: Rafael Tresaco | F9: 985600 | J9: J9
A10: Gabriel Barès | B10: 200000 | C10: Matia Barzic | D10: 800000 | E10: Adrián Pica | F10: 1916300 | G10: Ofrecer | J10: J10
A11: Ousmane Camara | B11: 1710000 | C11: Leonardo Buta | D11: 2290000 | E11: Arnau Comas | F11: 1573400 | G11: =G14+H2/4 | J11: J11
A12: Rafael Tresaco | B12: 790000 | C12: Jon Bautista | D12: 4400000 | E12: Jesús Owono | F12: 1379200 | J12: J12
A13: Michal Willmann | B13: 910000 | C13: Pedro López | D13: 1000000 | E13: Álvaro Rodríguez | F13: 2710000 | G13: Presupuesto | J13: J13
A14: Dani Requena | B14: 1160000 | C14: Mulattieri | D14: 6050001 | E14: Ousmane Camara | F14: 2557600 | G14: =G8+G5-G2+H5 | J14: J14
A15: Jaouab | B15: 950000 | C15: De La Fuente | D15: 7300001 | E15: Aarón Ochoa | F15: 600000 | J15: J15
A16: Anuar | B16: 3270000 | C16: Édgar Badía | D16: 3000001 | E16: Paulino | F16: 4220000 | J16: J16
B17: =SUM(B2:B16) | C17: Paulino | D17: 3940000 | E17: Pedro López | F17: 784800 | J17: J17
E18: Paulino | F18: 2482000 | J18: J18
J19: J19
J20: J20
J21: J21
J22: J22
J23: J23
J24: J24
J25: J25
J26: J26
J27: J27
J28: J28
J29: J29
J30: J30
... J42: J42

Sheet Mompia FC
C1: Altas | D1: Gastado | E1: Bajas | F1: Ingresado | G1: Gastado Total | H1: Valor Plantilla Actual | I1: Beneficio J | K1: Ultima Actualización | L1: =TODAY()
A2: Víctor Aznar | B2: 330000 | C2: Álex Lizancos | D2: 650000 | E2: Víctor Aznar | F2: 323900 | G2: =SUM(D:D) | H2: 35860000 | I2: 620000 | J2: J2 | K2: 45936
A3: Sergi Maestre | B3: 370000 | C3: Nico Melamed | D3: 8000000 | E3: Sergi Maestre | F3: 348200 | I3: 1110000 | J3: J3
A4: Javi Moreno | B4: 280000 | C4: Marc-Olivier Doué | D4: 1300000 | E4: Javi Moreno | F4: 271400 | G4: Ingresado Total | H4: Beneficio Total Jornadas | I4: =470000+232000 | J4: J4 | K4: Compras | L4: =COUNT('Mompia FC'!#REF!)+1
A5: Moussa Diarra | B5: 210000 | C5: Keidi Bare | D5: 1300000 | E5: Moussa Diarra | F5: 207000 | G5: =SUM(F:F) | H5: =SUM('Mompia FC'!$I$2:$I$7) | I5: 1370000 | J5: J5 | K5: Ventas | L5: =COUNT('Mompia FC'!$F$2:$F$27)+1
A6: Albert Lottin | B6: 640000 | C6: Ibrahima Koné | D6: 1750000 | E6: Marc-Olivier Doué | F6: 938100 | I6: 1330000 | J6: J6
A7: Carlos Marín | B7: 3630000 | C7: Jeremy Arévalo | D7: 300000 | E7: Keidi Bare | F7: 938300 | G7: Saldo Inicial | H7: Beneficio | I7: 980000 | J7: J7
A8: Anaitz Arbilla | B8: 1700000 | C8: Xavi Sintes | D8: 1400000 | E8: Albert Lottin | F8: 531800 | G8: 18740000 | H8: =G14-G8+H2-(40000000-G8)-H5 | J8: J8
A9: Sergio Escudero | B9: 1320000 | C9: Keidi Bare | D9: 1500000 | E9: Sergio Rodelas | F9: 487400 | J9: J9
A10: Jonathan Gómez | B10: 2100000 | C10: Théo Zidane | D10: 2500000 | E10: Ibrahima Koné | F10: 1130100 | G10: Ofrecer | J10: J10
A11: Yeray Cabanzón | B11: 2190000 | C11: Pablo Ramón | D11: 3500000 | E11: Álex Lizancos | F11: 687900 | G11: =G14+H2/4 | J11: J11
A12: Alberto del Moral | B12: 1420000 | C12: Kazunari Kita | D12: 200000 | E12: Alberto del Moral | F12: 1000300 | J12: J12
A13: Pedro Ortiz | B13: 2630000 | C13: Íñigo Sainz-Maza | D13: 2000000 | E13: Jonathan Gómez | F13: 1706500 | G13: Presupuesto | J13: J13
A14: Stipe Biuk | B14: 2380000 | C14: Álvaro Rodríguez | D14: 2710000 | E14: Théo Zidane | F14: 1877500 | G14: =G8+G5-G2+H5 | J14: J14
A15: García Pascual | B15: 1480000 | C15: Jon Morcillo | D15: 8000000 | E15: Kazunari Kita | F15: 166700 | J15: J15
A16: Sergio Rodelas | B16: 580000 | C16: Mathis Lachuer | D16: 6200000 | E16: Pedro Ortiz | F16: 1748500 | J16: J16
B17: =SUM(B2:B16) | C17: Aarón Ochoa | D17: 600000 | E17: Keidi Bare | F17: 701500 | J17: J17
C18: Toni Abad | D18: 980000 | E18: Íñigo Sainz-Maza | F18: 868500 | J18: J18
C19: Astiazaran | D19: 2800000 | E19: Yeray Cabanzón | F19: 2523900 | J19: J19
C20: Manu Hernando | D20: 3550000 | E20: Xavi Sintes | F20: 1486800 | J20: J20
C21: Egoitz Arana | D21: 350000 | E21: García Pascual | F21: 3700000 | J21: J21
C22: Plamen Andreev | D22: 2000000 | E22: Carlos Marín | F22: 3485300 | J22: J22
E23: Álvaro Rodríguez | F23: 1911300 | J23: J23
E24: Aarón Ochoa | F24: 382200 | J24: J24
E25: Sergio Escudero | F25: 2764900 | J25: J25
E26: Astiazaran | F26: 2121200 | J26: J26
E27: Egoitz Arana | F27: 219700 | J27: J27
E28: Sergio Escudero | F28: 2764900 | J28: J28
E29: Astiazaran | F29: 2121200 | J29: J29
E30: Sergio Escudero | F30: 2764900 | J30: J30
E31: Astiazaran | F31: 2121200 | J31: J31
E32: Sergio Escudero | F32: 2764900 | J32: J32
E33: Sergio Escudero | F33: 2121200 | J33: J33
E34: Sergio Escudero | F34: 2764900 | J34: J34
E35: Astiazaran | F35: 2121200 | J35: J35
E36: Sergio Escudero | J36: J36
E37: Astiazaran | J37: J37
J38: J38
J39: J39
J40: J40
...

Sheet La Piñera
C1: Altas | D1: Gastado | E1: Bajas | F1: Ingresado | G1: Gastado Total | H1: Valor Plantilla Actual | I1: Beneficio J | K1: Ultima Actualización | L1: =TODAY()
A2: Suleiman Camara | B2: 460000 | C2: Pau Sans | D2: 1800000 | E2: Suleiman Camara | F2: 430700 | G2: =SUM(D:D) | H2: 38560000 | I2: 710000 | J2: J2 | K2: 45936
A3: Alejandro Meléndez | B3: 590000 | C3: Melero | D3: 3950000 | E3: Alejandro Meléndez | F3: 558300 | I3: 1010000 | J3: J3
A4: Bicho | B4: 920000 | C4: Manuel Fuster | D4: 7300000 | E4: Bicho | F4: 1200000 | G4: Ingresado Total | H4: Beneficio Total Jornadas | I4: 1030000 | J4: J4 | K4: Compras | L4: =COUNT('La Piñera'!$D$2:$D$19)
A5: Fernando Martinez | B5: 1880000 | C5: Alfonso Herrero | D5: 5700000 | E5: Fernando Martinez | F5: 1811900 | G5: =SUM(F:F) | H5: =SUM('La Piñera'!$I$2:$I$7) | I5: 890000 | J5: J5 | K5: Ventas | L5: =COUNT('La Piñera'!$F$2:$F$22)
A6: Pablo Pérez | B6: 720000 | C6: Eric Curbelo | D6: 1050000 | E6: Pablo Pérez | F6: 678100 | I6: 1260000 | J6: J6
A7: Raúl Lizoain | B7: 1770000 | C7: Iker Kortajarena | D7: 4401000 | E7: Raúl Lizoain | F7: 1686200 | G7: Saldo Inicial | H7: Beneficio | I7: 1030000 | J7: J7
A8: Ro Abajas | B8: 200000 | C8: Xavi Moreno | D8: 320000 | E8: Ro Abajas | F8: 204200 | G8: 18820000 | H8: =G14-G8+H2-(40000000-G8)-H5 | J8: J8
A9: Ibrahima Koné | B9: 1540000 | C9: Rodri Suárez | D9: 950000 | E9: Ibrahima Koné | F9: 1750000 | J9: J9
A10: Mikel Rodriguez | B10: 850000 | C10: José Ángel Jurado | D10: 1280000 | E10: Mikel Rodriguez | F10: 844300 | G10: Ofrecer | J10: J10
A11: Quique Fornos | B11: 650000 | C11: Dani Escriche | D11: 2000000 | E11: Quique Fornos | F11: 551400 | G11: =G14+H2/4 | J11: J11
A12: Anderson Arroyo | B12: 2920000 | C12: Agustín Sienra | D12: 899010 | E12: José Arnaiz | F12: 2516300 | J12: J12
A13: Víctor García | B13: 740000 | C13: Fer Niño | D13: 7211000 | E13: Melero | F13: 2891400 | G13: Presupuesto | J13: J13
A14: Hongla | B14: 2250000 | C14: Jorge Pulido | D14: 5524000 | E14: Anderson Arroyo | F14: 3800000 | G14: =G8+G5-G2+H5 | J14: J14
A15: Víctor Meseguer | B15: 2450000 | C15: Jan Salas | D15: 545000 | E15: Eric Curbelo | F15: 885400 | J15: J15
A16: José Arnaiz | B16: 3240000 | C16: David Mella | D16: 4550000 | E16: Xavi Moreno | F16: 334700 | J16: J16
B17: =SUM(B2:B16) | C17: Facundo González | D17: 2170001 | E17: José Ángel Jurado | F17: 1097700 | J17: J17
C18: Martí Vilà | D18: 200010 | E18: Agustín Sienra | F18: 743500 | J18: J18
C19: José Lazo | D19: 601000 | E19: Hongla | F19: 2366600 | J19: J19
E20: Pau Sans | F20: 1500000 | J20: J20
E21: Jan Salas | F21: 485900 | J21: J21
E22: Víctor García | F22: 803800 | J22: J22
J23: J23
J24: J24
J25: J25
J26: J26
J27: J27
J28: J28
J29: J29
J30: J30
J31: J31
J32: J32
J33: J33
J34: J34
... J42: J42

Sheet Costa norte
A1: Pedro López | B1: 680000 | C1: Altas | D1: Gastado | E1: Bajas | F1: Ingresado | G1: Gastado Total | H1: Valor Plantilla Actual | I1: Beneficio J | K1: Ultima Actualización | L1: =TODAY()
A2: José Antonio Caro | B2: 1340000 | C2: Alex Lebarbier | D2: 1900000 | E2: Jokin Gabilondo | F2: 502100 | G2: =SUM(D:D) | H2: 43890000 | I2: 930000 | J2: J2 | K2: 45936
A3: Fran Gámez | B3: 1930000 | C3: Antonio Puertas | D3: 6000000 | E3: José Antonio Caro | F3: 1295200 | I3: 990000 | J3: J3
A4: Imanol García | B4: 1750000 | C4: Unax Agote | D4: 800000 | E4: Weissman | F4: 667100 | G4: Ingresado Total | H4: Beneficio Total Jornadas | I4: 950000 | J4: J4 | K4: Compras | L4: =COUNT('Costa norte'!$D$2:$D$10)
A5: Thomas Carrique | B5: 1250000 | C5: Iñigo Córdoba | D5: 2800000 | E5: Ronaldo | F5: 432800 | G5: =SUM(F:F) | H5: =SUM('Costa norte'!$I$2:$I$5) | I5: 1890000 | J5: J5 | K5: Ventas | L5: =COUNT('Costa norte'!$F$2:$F$14)
A6: Diego González | B6: 400000 | C6: Aitor Fraga | D6: 3900000 | E6: José Ángel Jurado | F6: 1280000 | I6: =480000+156000 | J6: J6
A7: Jokin Gabilondo | B7: 500000 | C7: Anderson Arroyo | D7: 3800000 | E7: Diego González | F7: 361800 | G7: Saldo Inicial | H7: Beneficio | I7: 600000 | J7: J7
A8: Agus Medina | B8: 4320000 | C8: Guilherme Fernandes | D8: 3700000 | E8: Javi Martínez | F8: 1194900 | G8: =40000000-B16 | H8: =G14-G8+H2-(40000000-G8)-H5 | J8: J8
A9: Javi Martínez | B9: 1120000 | C9: Ale García | D9: 7000000 | E9: Pedro López | F9: 1000000 | J9: J9
A10: Ignasi Vilarrasa | B10: 3200000 | C10: Florian Miguel | D10: 4270000 | E10: Anderson Arroyo | F10: 2817200 | G10: Ofrecer | J10: J10
A11: José Ángel Jurado | B11: 1440000 | E11: Aitor Fraga | F11: 2693600 | G11: =G14+H2/4 | J11: J11
A12: Ronaldo | B12: 430000 | E12: Iñigo Córdoba | F12: 1922100 | J12: J12
A13: Brian Ocampo | B13: 1740000 | E13: Imanol García | F13: 1497300 | G13: Presupuesto | J13: J13
A14: Souleymane Faye | B14: 470000 | E14: Unax Agote | F14: 504400 | G14: =G8+G5-G2+H5 | J14: J14
A15: Weissman | B15: 680000 | E15: Unax Agote | F15: 504400 | J15: J15
B16: =SUM(B1:B15) | E16: Unax Agote | F16: 504400 | J16: J16
E17: Unax Agote | F17: 504400 | J17: J17
E18: Unax Agote | F18: 504400 | J18: J18
E19: Unax Agote | F19: 504400 | J19: J19
E20: Unax Agote | F20: 504400 | J20: J20
E21: Unax Agote | J21: J21
J22: J22
J23: J23
J24: J24
J25: J25
J26: J26
J27: J27
J28: J28
J29: J29
J30: J30
J31: J31
J32: J32
J33: J33
... J42: J42

Sheet Lábaro FC
A1: Jugadores | B1: Valor dia 0 | C1: Altas | D1: Gastado | E1: Bajas | F1: Ingresado | G1: Gastado Total | H1: Valor Plantilla Actual | I1: Beneficio J | K1: Ultima Actualización | L1: =TODAY()
A2: Guillermo Vallejo | B2: 670000 | G2: =SUM(D:D) | H2: 26040000 | I2: 810000 | J2: J2 | K2: 45936
A3: Iker Álvarez | B3: 1330000 | I3: 1250000 | J3: J3
A4: Rubén González | B4: 2020000 | G4: Ingresado Total | H4: Beneficio Total Jornadas | I4: 1130000 | J4: J4 | K4: Compras | L4: =COUNT('Lábaro FC'!$D$2)
A5: Fernando Medrano | B5: 460000 | G5: =SUM(F:F) | H5: =SUM('Lábaro FC'!$I$2:$I$7) | I5: 1010000 | J5: J5 | K5: Ventas | L5: =COUNT('Lábaro FC'!$F$2)
A6: Lorenzo Aguado | B6: 270000 | I6: 1140000 | J6: J6
A7: Diego Hormigo | B7: 440000 | G7: Saldo Inicial | H7: Beneficio | I7: 860000 | J7: J7
A8: Iker Córdoba | B8: 240000 | G8: 18950000 | H8: =G14-G8+H2-(40000000-G8)-H5 | J8: J8
A9: Stanko Juric | B9: 3330000 | J9: J9
A10: Sebas Moyano | B10: 3160000 | G10: Ofrecer | J10: J10
A11: Sergio Molina | B11: 1670000 | G11: =G8+H2/4 | J11: J11
A12: Villahermosa | B12: 1150000 | J12: J12
A13: Bless Aniekan | B13: 150000 | G13: Presupuesto | J13: J13
A14: Awer Mabil | B14: 3580000 | G14: =G8+G5-G2+H5 | J14: J14
A15: Ekain Orobengoa | B15: 310000 | J15: J15
A16: Jorge Pascual | B16: 2270000 | J16: J16
B17: 21050000 | J17: J17
J18: J18
J19: J19
J20: J20
J21: J21
J22: J22
J23: J23
J24: J24
J25: J25
J26: J26
J27: J27
J28: J28
J29: J29
... J42: J42

Sheet Cacafuti
C1: Altas | D1: Gastado | E1: Bajas | F1: Ingresado | G1: Gastado Total | H1: Valor Plantilla Actual | I1: Beneficio J | K1: Ultima Actualización | L1: =TODAY()
A2: Jonmi Magunagoitia | B2: 3410000 | C2: Sangalli | D2: 3125001 | E2: Mamadou Traoré | F2: 144500 | G2: =SUM(D:D) | H2: 41260000 | I2: 930000 | J2: J2 | K2: 45936
A3: Egoitz Arana | B3: 200000 | C3: Dani Barcia | D3: 4680000 | E3: Joaquín González | F3: 235400 | I3: 1370000 | J3: J3
A4: Carlos Puga | B4: 1610000 | C4: Javier Castro | D4: 4581000 | E4: Hodei Arrillaga | F4: 566300 | G4: Ingresado Total | H4: Beneficio Total Jornadas | I4: 950000 | J4: J4 | K4: Compras | L4: =COUNT(Cacafuti!$D$2:$D$11)
A5: Sergio Barcia | B5: 2050000 | C5: Victor Valverde | D5: 1004041 | E5: Manu Trigueros | F5: 2199700 | G5: =SUM(F:F) | H5: =SUM(Cacafuti!$I$2:$I$7) | I5: 1310000 | J5: J5 | K5: Ventas | L5: =COUNT(Cacafuti!$F$2:$F$10)
A6: Hodei Arrillaga | B6: 690000 | C6: Àlex Corredera | D6: 4950010 | E6: Peru Nolaskoain | F6: 1649400 | I6: 920000 | J6: J6
A7: Pablo García | B7: 1170000 | C7: Cristian Rodríguez | D7: 1120000 | E7: Pablo García | F7: 907400 | G7: Saldo Inicial | H7: Beneficio | I7: 1110000 | J7: J7
A8: Tincho Conde | B8: 560000 | C8: Eddahchouri | D8: 6251001 | E8: Egoitz Arana | F8: 350000 | G8: =40000000-B17 | H8: =G14-G8+H2-(40000000-G8)-H5 | J8: J8
A9: Isma Ruiz | B9: 3370000 | C9: Gorka Carrera | D9: 1460000 | E9: De la Rosa | F9: 386500 | J9: J9
A10: Peru Nolaskoain | B10: 2550000 | C10: Baba | D10: 775010 | E10: Victor Valverde | F10: 692400 | G10: Ofrecer | J10: J10
A11: Manu Trigueros | B11: 2690000 | C11: Diego Villares | D11: 3860001 | G11: =G14+H2/4 | J11: J11
A12: Nico Toca | B12: 160000 | J12: J12
A13: Joaquín González | B13: 240000 | G13: Presupuesto | J13: J13
A14: Samed Bazdar | B14: 1640000 | G14: =G8+G5-G2+H5 | J14: J14
A15: De la Rosa | B15: 640000 | J15: J15
A16: Mamadou Traoré | B16: 150000 | J16: J16
B17: =SUM(B2:B16) | J17: J17
J18: J18
J19: J19
J20: J20
J21: J21
J22: J22
J23: J23
J24: J24
J25: J25
J26: J26
J27: J27
J28: J28
J29: J29
... J42: J42

Sheet Luis Padrique
A1: Víctor Aznar | B1: 920000 | C1: Altas | D1: Gastado | E1: Bajas | F1: Ingresado | G1: Gastado Total | H1: Valor Plantilla Actual | I1: Beneficio J | K1: Ultima Actualización | L1: =TODAY()
A2: Fernando Martinez | B2: 1470000 | C2: Álex Martín | D2: 685000 | E2: Iñaki Rupérez | F2: 1127200 | G2: =SUM(D:D) | H2: 44490000 | I2: 930000 | J2: J2 | K2: 45936
A3: Julio Alonso | B3: 1380000 | C3: Jonathan Viera | D3: 8521000 | E3: Fernando Martinez | F3: 1413200 | I3: 1090000 | J3: J3
A4: Iván Garriel | B4: 150000 | C4: Yeremay Hernández | D4: 13852000 | E4: Einar Galilea | F4: 772100 | G4: Ingresado Total | H4: Beneficio Total Jornadas | I4: 760000 | J4: J4 | K4: Compras | L4: =COUNT('Luis Padrique'!$D$2:$D$14)
A5: Iñaki Rupérez | B5: 1120000 | C5: Pau Casadesús | D5: 325000 | E5: Escalante | F5: 617600 | G5: =SUM(F:F) | H5: =SUM('Luis Padrique'!$I$2:$I$7) | I5: 960000 | J5: J5 | K5: Ventas | L5: =COUNT('Luis Padrique'!$F$2:$F$20)
A6: Einar Galilea | B6: 800000 | C6: Andrés Martín | D6: 14525000 | E6: Ramón Enríquez | F6: 159600 | I6: 1380000 | J6: J6
A7: Brais Martínez | B7: 250000 | C7: Diego Murillo | D7: 515000 | E7: Brais Martínez | F7: 218600 | G7: Saldo Inicial | H7: Beneficio | I7: 1350000 | J7: J7
A8: Iván Alejo | B8: 3880000 | C8: Aguirregabiria | D8: 1852000 | E8: Kirian Rodríguez | F8: 3145800 | G8: =40000000-B16 | H8: =G14-G8+H2-(40000000-G8)-H5 | J8: J8
A9: Jon Magunacelaya | B9: 1630000 | C9: Gustavo Puerta | D9: 4865000 | E9: Dani Escriche | F9: 2000000 | J9: J9
A10: Kirian Rodríguez | B10: 3740000 | C10: Aleix Garrido | D10: 5535000 | E10: Jonathan Viera | F10: 5484700 | G10: Ofrecer | J10: J10
A11: Escalante | B11: 650000 | C11: Mikel Rodriguez | D11: 1515000 | E11: Gaspar Campos | F11: 2565000 | G11: =G14+H2/4 | J11: J11
A12: Ramón Enríquez | B12: 160000 | C12: Andrés Fernández | D12: 2956000 | E12: Manu Justo | F12: 884500 | J12: J12
A13: Dani Escriche | B13: 1140000 | C13: Brian Cipenga | D13: 5800000 | E13: Álex Martín | F13: 426200 | G13: Presupuesto | J13: J13
A14: Gaspar Campos | B14: 2940000 | C14: Peru Nolaskoain | D14: 1285000 | E14: Iván Garriel | F14: 522900 | G14: =G8+G5-G2+H5 | J14: J14
A15: Manu Justo | B15: 1030000 | E15: Víctor Aznar | F15: 2052600 | J15: J15
B16: 21260000 | E16: Julio Alonso | F16: 2257800 | J16: J16
E17: Iván Alejo | F17: 5800000 | J17: J17
E18: Aguirregabiria | F18: 973400 | J18: J18
E19: Aleix Garrido | F19: 4807700 | J19: J19
E20: Diego Murillo | F20: 760100 | J20: J20
E21: Diego Murillo | F21: 760100 | J21: J21
E22: Diego Murillo | F22: 760100 | J22: J22
E23: Diego Murillo | F23: 760100 | J23: J23
E24: Diego Murillo | F24: 760100 | J24: J24
J25: J25
J26: J26
J27: J27
J28: J28
J29: J29
J30: J30
J31: J31
J32: J32
J33: J33
J34: J34
J35: J35
J36: J36
... J42: J42

Sheet Real Garrucho
A1: Jugadores | B1: Valor dia 0 | C1: Altas | D1: Gastado | E1: Bajas | F1: Ingresado | G1: Gastado Total | H1: Valor Plantilla Actual | I1: Beneficio | K1: Ultima Actualización | L1: =TODAY()
A2: Juan Soriano | B2: 3300000 | C2: Iza Carcelen | D2: 4200000 | E2: Selu Diallo | F2: 649700 | G2: =SUM(D:D) | H2: 37730000 | I2: 1110000 | J2: J2 | K2: 45936
A3: Selu Diallo | B3: 740000 | C3: Marcos de Sousa | D3: 3000000 | E3: Flakus Bosilj | F3: 466200 | I3: 1030000 | J3: J3
A4: Kevin Vázquez | B4: 480000 | C4: Chuki | D4: 5000000 | E4: Áron Yaakobishvili | F4: 2000000 | G4: Ingresado Total | H4: Beneficio Total Jornadas | I4: 920000 | J4: J4 | K4: Compras | L4: =COUNT('Real Garrucho'!$D$2:$D$22)
A5: Sergio Gonzalez | B5: 1650000 | C5: Mateo Mejía | D5: 1190000 | E5: Pau Sans | F5: 1800000 | G5: =SUM(F:F) | H5: =SUM('Real Garrucho'!$I$2:$I$43) | I5: 990000 | J5: J5 | K5: Ventas | L5: =COUNT('Real Garrucho'!$F$2:$F$26)
A6: Iñaki Rupérez | B6: 1360000 | C6: David Torres | D6: 6500000 | E6: Pedro Alemañ | F6: 542700 | I6: 1300000 | J6: J6
A7: Yaakobishvili | B7: 1160000 | C7: Dani Barcia | D7: 3115000 | E7: Yann Kembo | F7: 143400 | G7: Saldo Inicial | H7: Beneficio | J7: J7
A8: Yann Kembo | B8: 160000 | C8: Sergi Enrich | D8: 3515000 | E8: Selim Amallah | F8: 2096900 | G8: 18950000 | H8: =G14-G8+H2-(40000000-G8)-H5 | J8: J8
A9: Flakus Bosilj | B9: 480000 | C9: Alfred Caicedo | D9: 320000 | E9: Yaakobishvili | F9: 891600 | J9: J9
A10: Ignacio Martín | B10: 2440000 | C10: Pablo Sáenz | D10: 2000000 | E10: Iñaki Rupérez | F10: 1134100 | G10: Ofrecer | J10: J10
A11: Liberto | B11: 1040000 | C11: Gregorio Sierra | D11: 3500000 | E11: Sergio Gonzalez | F11: 1216200 | G11: =G14+H2/4 | J11: J11
A12: Selim Amallah | B12: 2640000 | C12: Pablo Tomeo | D12: 7500000 | E12: Marcos de Sousa | F12: 1686700 | J12: J12
A13: Pedro Alemañ | B13: 590000 | C13: Javier Martón | D13: 5620000 | E13: Eddahchouri | F13: 4149400 | G13: Presupuesto | J13: J13
A14: Eddahchouri | B14: 3180000 | C14: Astiazaran | D14: 2700000 | E14: Mateo Mejía | F14: 1178500 | G14: =G8+G5-G2+H5 | J14: J14
A15: Yaakobishvili | B15: 210000 | C15: Marc Doménech | D15: 5000000 | E15: Sergi Enrich | F15: 3033800 | J15: J15
A16: Pau Sans | B16: 1620000 | C16: Suso | D16: 6000000 | E16: Dani Barcia | F16: 4680000 | J16: J16
B17: =SUM('Real Garrucho'!$B$2:$B$16) | C17: Álex Lizancos | D17: 1600000 | E17: Iza Carcelen | F17: 2851400 | J17: J17
C18: Bassinga | D18: 330000 | E18: Ignacio Martín | F18: 2919800 | J18: J18
C19: Jesús Álvarez | D19: 1200000 | E19: Liberto | F19: 1319300 | J19: J19
C20: Quagliata | D20: 1900000 | E20: Chuki | F20: 5048700 | J20: J20
C21: Théo Zidane | D21: 1610000 | E21: Pablo Sáenz | F21: 1732300 | J21: J21
C22: Iván Alejo | D22: 5800000 | E22: Kevin Vázquez | F22: 418100 | J22: J22
E23: Astiazaran | F23: 2800000 | J23: J23
E24: Alfred Caicedo | F24: 316100 | J24: J24
E25: Marc Doménech | F25: 3843200 | J25: J25
E26: Théo Zidane | F26: 1460300 | J26: J26
J27: J27
J28: J28
J29: J29
J30: J30
J31: J31
J32: J32
J33: J33
J34: J34
J35: J35
J36: J36
J37: J37
J38: J38
... J42: J42
I43: -1000000 | J43: Gracieta 16M

Sheet Tuma Tuma Nin
B1: Valor Dia 0 | C1: Altas | D1: Gastado | E1: Bajas | F1: Ingresado | G1: Gastado Total | H1: Valor Plantilla Actual | I1: Beneficio J | K1: Ultima Actualización | L1: =TODAY()
A2: Miguel Bañuz | B2: 380000 | E2: Miguel Atienza | F2: 3520000 | G2: =SUM(D:D) | H2: 11480000 | I2: 1310000 | J2: J2 | K2: 45936
A3: Eric Puerto | B3: 220000 | I3: 1370000 | J3: J3
A4: Redruello | B4: 1240000 | G4: Ingresado Total | H4: Beneficio Total Jornadas | I4: 1530000 | J4: J4 | K4: Compras | L4: =COUNT('Tuma Tuma Nin'!$D$2)
A5: Mario García | B5: 2820000 | G5: =SUM(F:F) | H5: =SUM('Tuma Tuma Nin'!$I$2:$I$7) | I5: 1040000 | J5: J5 | K5: Ventas | L5: =COUNT('Tuma Tuma Nin'!$F$2)
A6: Javi Sánchez | B6: 2710000 | I6: 1530000 | J6: J6
A7: Matos | B7: 1820000 | G7: Saldo Inicial | H7: Beneficio | I7: 1530000 | J7: J7
A8: Astigarraga | B8: 180000 | G8: 16800000 | H8: =G14-G8+H2-(40000000-G8)-H5 | J8: J8
A9: Miguel Atienza | B9: 2910000 | J9: J9
A10: Roberto López | B10: 3810000 | G10: Ofrecer | J10: J10
A11: Théo Le Normand | B11: 590000 | G11: =G14+H2/4 | J11: J11
A12: Lucas Robertone | B12: 2580000 | J12: J12
A13: Rafa Rodríguez | B13: 2580000 | G13: Presupuesto | J13: J13
A14: Nick Markanich | B14: 600000 | G14: =G8+G5-G2+H5 | J14: J14
A15: Cristian Herrera | B15: 430000 | J15: J15
A16: Aitor Uzkudun | B16: 330000 | J16: J16
B17: 23200000 | J17: J17
J18: J18
J19: J19
J20: J20
J21: J21
J22: J22
J23: J23
J24: J24
J25: J25
J26: J26
J27: J27
J28: J28
J29: J29
... J42: J42

Sheet Id_Jugadores
A1: Jugador | B1: ID
A2: Villalibre | B2: 1
A3: Agus Medina | B3: 2
A4: César Gelabert | B4: 3
A5: Javier Martón | B5: 4
A6: Anaitz Arbilla | B6: 5
A7: Ale García | B7: 6
A8: Andrés Martín | B8: 7
A9: Jon Morcillo | B9: 8
A10: Chuki | B10: 9
A11: Amath | B11: 10
A12: Enrique Clemente | B12: 11
A13: Léo Baptistão | B13: 12
... A525: Iker Córdoba | B525: 524

Sheet Clausulas
H2: Buscar Jugador: | I2: David Torres
H3: Clausula: | I3: =VLOOKUP(I2,Clausulas!$A$5:$F$46,5,0)
A4: Fichajes | B4: Clausula | C4: Usuario | D4: ID | E4: Clausula Final | F4: Repetido?
A5: Lander Olaetxea | B5: 3180000 | C5: Cachoneros | D5: =VLOOKUP(A5,Id_Jugadores!A$2:B$523,2,0) | E5: =_xlfn.MAXIFS(Clausulas!$B$5:$B$46,Clausulas!$D$5:$D$46,Clausulas!$D5) | F5: =IF(COUNTIF(Clausulas!$D$5:$D$46,D5)=2,"Si","No")
A6: Marc Cardona | B6: 770100 | C6: Cachoneros | D6: =VLOOKUP(A6,Id_Jugadores!A$2:B$523,2,0) | E6: =_xlfn.MAXIFS(Clausulas!$B$5:$B$46,Clausulas!$D$5:$D$46,Clausulas!$D6) | F6: =IF(COUNTIF(Clausulas!$D$5:$D$46,D6)=2,"Si","No")
A7: Adrián Rodríguez | B7: 670110 | C7: Cachoneros | D7: =VLOOKUP(A7,Id_Jugadores!A$2:B$523,2,0) | E7: =_xlfn.MAXIFS(Clausulas!$B$5:$B$46,Clausulas!$D$5:$D$46,Clausulas!$D7) | F7: =IF(COUNTIF(Clausulas!$D$5:$D$46,D7)=2,"Si","No")
A8: Jastin Garcia | B8: 691000 | C8: Cachoneros | D8: =VLOOKUP(A8,Id_Jugadores!A$2:B$523,2,0) | E8: =_xlfn.MAXIFS(Clausulas!$B$5:$B$46,Clausulas!$D$5:$D$46,Clausulas!$D8) | F8: =IF(COUNTIF(Clausulas!$D$5:$D$46,D8)=2,"Si","No")
A9: Mario Climent | B9: 4000000 | C9: Guacamayos | D9: =VLOOKUP(A9,Id_Jugadores!A$2:B$523,2,0) | E9: =_xlfn.MAXIFS(Clausulas!$B$5:$B$46,Clausulas!$D$5:$D$46,Clausulas!$D9) | F9: =IF(COUNTIF(Clausulas!$D$5:$D$46,D9)=2,"Si","No")
A10: Álex Calatrava | B10: 8000000 | C10: Guacamayos | D10: =VLOOKUP(A10,Id_Jugadores!A$2:B$523,2,0) | E10: =_xlfn.MAXIFS(Clausulas!$B$5:$B$46,Clausulas!$D$5:$D$46,Clausulas!$D10) | F10: =IF(COUNTIF(Clausulas!$D$5:$D$46,D10)=2,"Si","No")
A11: Amatucci | B11: 3300000 | C11: Guacamayos | D11: =VLOOKUP(A11,Id_Jugadores!A$2:B$523,2,0) | E11: =_xlfn.MAXIFS(Clausulas!$B$5:$B$46,Clausulas!$D$5:$D$46,Clausulas!$D11) | F11: =IF(COUNTIF(Clausulas!$D$5:$D$46,D11)=2,"Si","No")
A12: Iza Carcelen | B12: 4200000 | C12: Real Garruchos | D12: =VLOOKUP(A12,Id_Jugadores!A$2:B$523,2,0) | E12: =_xlfn.MAXIFS(Clausulas!$B$5:$B$46,Clausulas!$D$5:$D$46,Clausulas!$D12) | F12: =IF(COUNTIF(Clausulas!$D$5:$D$46,D12)=2,"Si","No")
A13: Marcos de Sousa | B13: 3000000 | C13: Real Garruchos | D13: =VLOOKUP(A13,Id_Jugadores!A$2:B$523,2,0) | E13: =_xlfn.MAXIFS(Clausulas!$B$5:$B$46,Clausulas!$D$5:$D$46,Clausulas!$D13) | F13: =IF(COUNTIF(Clausulas!$D$5:$D$46,D13)=2,"Si","No")
A14: Chuki | B14: 5000000 | C14: Real Garruchos | D14: =VLOOKUP(A14,Id_Jugadores!A$2:B$523,2,0) | E14: =_xlfn.MAXIFS(Clausulas!$B$5:$B$46,Clausulas!$D$5:$D$46,Clausulas!$D14) | F14: =IF(COUNTIF(Clausulas!$D$5:$D$46,D14)=2,"Si","No")
A15: Mateo Mejía | B15: 1190000 | C15: Real Garruchos | D15: =VLOOKUP(A15,Id_Jugadores!A$2:B$523,2,0) | E15: =_xlfn.MAXIFS(Clausulas!$B$5:$B$46,Clausulas!$D$5:$D$46,Clausulas!$D15) | F15: =IF(COUNTIF(Clausulas!$D$5:$D$46,D15)=2,"Si","No")
A16: David Torres | B16: 6500000 | C16: Real Garruchos | D16: =VLOOKUP(A16,Id_Jugadores!A$2:B$523,2,0) | E16: =_xlfn.MAXIFS(Clausulas!$B$5:$B$46,Clausulas!$D$5:$D$46,Clausulas!$D16) | F16: =IF(COUNTIF(Clausulas!$D$5:$D$46,D16)=2,"Si","No")
... A41: Mika Mármol | B41: 4160000 | C41: Llaule | D41: =VLOOKUP(A41,Id_Jugadores!A$2:B$523,2,0) | E41: =_xlfn.MAXIFS(Clausulas!$B$5:$B$46,Clausulas!$D$5:$D$46,Clausulas!$D41) | F41: =IF(COUNTIF(Clausulas!$D$5:$D$46,D41)=2,"Si","No")
A42: Mario Jimenez | B42: 250000 | C42: Llaule | D42: Fuera de la Liga | E42: =_xlfn.MAXIFS(Clausulas!$B$5:$B$46,Clausulas!$D$5:$D$46,Clausulas!$D42) | F42: =IF(COUNTIF(Clausulas!$D$5:$D$46,D42)=2,"Si","No")
A43: David Torres | B43: 1560000 | C43: Llaule | D43: =VLOOKUP(A43,Id_Jugadores!A$2:B$523,2,0) | E43: =_xlfn.MAXIFS(Clausulas!$B$5:$B$46,Clausulas!$D$5:$D$46,Clausulas!$D43) | F43: =IF(COUNTIF(Clausulas!$D$5:$D$46,D43)=2,"Si","No")
A44: Riki Rodríguez | B44: 3840000 | C44: Llaule | D44: =VLOOKUP(A44,Id_Jugadores!A$2:B$523,2,0) | E44: =_xlfn.MAXIFS(Clausulas!$B$5:$B$46,Clausulas!$D$5:$D$46,Clausulas!$D44) | F44: =IF(COUNTIF(Clausulas!$D$5:$D$46,D44)=2,"Si","No")
A45: Juan Pérez | B45: 400000 | C45: Llaule | D45: =VLOOKUP(A45,Id_Jugadores!A$2:B$523,2,0) | E45: =_xlfn.MAXIFS(Clausulas!$B$5:$B$46,Clausulas!$D$5:$D$46,Clausulas!$D45) | F45: =IF(COUNTIF(Clausulas!$D$5:$D$46,D45)=2,"Si","No")
A46: Íñigo Sainz-Maza | B46: 2160000 | C46: Llaule | D46: =VLOOKUP(A46,Id_Jugadores!A$2:B$523,2,0) | E46: =_xlfn.MAXIFS(Clausulas!$B$5:$B$46,Clausulas!$D$5:$D$46,Clausulas!$D46) | F46: =IF(COUNTIF(Clausulas!$D$5:$D$46,D46)=2,"Si","No")
